Fixed `pytest_response.app.Response` and added another exception `~pytest_response.exceptions.DatabaseNotFound`.
